<?xml version="1.0"?>
<robot name="inverted_pendulum" xmlns:xacro="http://ros.org/wiki/xacro">

  <!-- <link name="world"/> -->

  <!-- ================= Base Link ================= -->
  <link name="base_link">
    <inertial>
      <mass value="1.0"/>
      <origin xyz="0 0 0"/>
      <inertia ixx="0.01" ixy="0.0" ixz="0.0" iyy="0.01" iyz="0.0" izz="0.01"/>
    </inertial>
    <visual>
      <geometry>
        <box size="0.03 0.2 0.2"/>
      </geometry>
      <material name="blue">
        <color rgba="0 0 1 1"/>
      </material>
    </visual>
    <collision>
      <geometry>
        <box size="0.03 0.2 0.2"/>
      </geometry>
    </collision>
  </link>

  <!-- ================= Base to World ================= -->
  <!-- <joint name="base_to_world" type="fixed">
    <parent link="world"/>
    <child link="base_link"/>
    <origin xyz="0 0 0.05" rpy="0 0 0"/>
  </joint> -->

  <link name="wheel_left">
    <inertial>
      <mass value="0.2"/>
      <origin xyz="0 0 0" rpy="0 0 0"/>
      <inertia ixx="0.115" iyy="0.115" izz="0.208"
           ixy="0.0" ixz="0.0" iyz="0.0"/>
    </inertial>
    <visual>
      <origin xyz="0 0 0" rpy="0 0 0"/>
      <geometry>
        <cylinder radius="0.05" length="0.02"/>
      </geometry>
      <material name="black">
        <color rgba="0 0 0 1"/>
      </material>
    </visual>
    <collision>
      <origin xyz="0 0 0" rpy="0 0 0"/>
      <geometry>
        <cylinder radius="0.05" length="0.02"/>
      </geometry>
    </collision>
  </link>

  <joint name="wheel_left_joint" type="continuous">
    <parent link="base_link"/>
    <child link="wheel_left"/>
    <origin xyz="0 0.12 -0.1" rpy="1.57 0 0"/>
    <axis xyz="0 0 1"/>
  </joint>

  <link name="wheel_right">
    <inertial>
      <mass value="0.2"/>
      <origin xyz="0 0 0"/>
      <inertia ixx="0.115" iyy="0.115" izz="0.208"
           ixy="0.0" ixz="0.0" iyz="0.0"/>
    </inertial>
    <visual>
      <origin xyz="0 0 0" rpy="0 0 0"/>
      <geometry>
        <cylinder radius="0.05" length="0.02"/>
      </geometry>
      <material name="black">
        <color rgba="0 0 0 1"/>
      </material>
    </visual>
    <collision>
      <origin xyz="0 0 0" rpy="0 0 0"/>
      <geometry>
        <cylinder radius="0.05" length="0.02"/>
      </geometry>
    </collision>
  </link>

  <joint name="wheel_right_joint" type="continuous">
    <parent link="base_link"/>
    <child link="wheel_right"/>
    <origin xyz="0 -0.12 -0.1" rpy="1.57 0 0"/>
    <axis xyz="0 0 1"/>
  </joint>

  <!-- ================= Pole ================= -->
  <!-- <link name="pole_link">
    <inertial>
      <mass value="0.5"/>
      <origin xyz="0 0 0.1"/>
      <inertia ixx="0.115" iyy="0.115" izz="0.208"
           ixy="0.0" ixz="0.0" iyz="0.0"/>
    </inertial>
    <visual>
      <origin xyz="0 0 0.1"/>
      <geometry>
        <cylinder radius="0.02" length="0.2"/>
      </geometry>
      <material name="red">
        <color rgba="1 0 0 1"/>
      </material>
    </visual>
    <collision>
      <origin xyz="0 0 0.1"/>
      <geometry>
        <cylinder radius="0.02" length="0.2"/>
      </geometry>
    </collision>
  </link>

  <joint name="pole_joint" type="continuous">
    <parent link="base_link"/>
    <child link="pole_link"/>
    <origin xyz="0 0 0.025" rpy="0 0 0"/>
    <axis xyz="0 1 0"/>
  </joint> -->

  <!-- ================= Gazebo Parameters ================= -->
  <!-- <ros2_control name="MyRobotHardware" type="system">
    <hardware>
     <plugin>gz_ros2_control/GazeboSimSystem</plugin>
      <joint name="wheel_left_joint">
        <command_interfaces>
          <interface>position</interface>
        </command_interfaces>
        <state_interfaces>
          <interface>position</interface>
        </state_interfaces>
      </joint>
      <joint name="wheel_right_joint">
        <command_interfaces>
          <interface>position</interface>
        </command_interfaces>
        <state_interfaces>
          <interface>position</interface>
        </state_interfaces>
      </joint>
    </hardware>
  </ros2_control> -->


<ros2_control name="GazeboSimSystem" type="system">
  <hardware>
    <plugin>gz_ros2_control/GazeboSimSystem</plugin>
  </hardware>
  <joint name="wheel_left_joint">
    <command_interface name="position">
    </command_interface>
    <state_interface name="position">
    </state_interface>
  </joint>
  <joint name="wheel_right_joint">
    <command_interface name="position">
    </command_interface>
    <state_interface name="position">
    </state_interface>
  </joint>
</ros2_control>


  <gazebo reference="base_link">
    <mu1>1</mu1>
    <mu2>1</mu2>
    <kp>100000</kp>
    <kd>1</kd>
    <bounce>0.5</bounce>
    <material>Gazebo/Blue</material>
  </gazebo>
</robot>